Workbook

Sheet Start Here
A1: Trade Job Quote & Change Order Workbook
A2: by Knackdesk · knackdesk.com
A4: HOW TO USE
A5: 1. Settings: your labour cost rate, overhead percentage, target profit margin, markups for change orders and subcontractors, and the deposit share.
A6: 2. Quote: list materials (quantity × unit cost), labour tasks (hours at your cost rate) and subcontractors. Overhead and margin roll up into the quote price, profit, markup and deposit. Copy the sheet for each new quote.
A7: 3. Change Orders: one row per change with materials, hours and subcontractor cost. Your markups give the change price; the revised contract total updates after every row.
A8: 4. Jobs: one row per job with quoted price, change orders, actual materials, hours and subs, invoiced and paid. Cost, overhead, profit, margin and outstanding are calculated.
A9: 5. Summary: totals and margins across jobs, outstanding balances and how many jobs fell below the target margin.
A11: LEGEND
A12: Blue text = a cell you type into. Black text = a formula, leave it alone. Yellow fill = key inputs.
A13: Blue cells that already contain a formula (rates and markups pulled from Settings) may be overwritten per line.
A15: DEFINITIONS
... A19: Fixed figures, before tax. Arithmetic only; not legal, contract or tax advice. Support: hello@knackdesk.com

Sheet Settings
A1: Settings
A2: Labour cost rate per hour | B2: 45 | C2: What an hour costs you: wages, contributions, paid downtime. Not what you charge.
A3: Overhead (% of direct cost) | B3: 15 | C3: A year of overhead ÷ a year of direct job cost.
A4: Target profit margin (% of price) | B4: 20 | C4: Profit as a share of the quote price.
A5: Subcontractor markup (%) | B5: 10 | C5: Applied to subcontractor cost on quotes and change orders.
A6: Change-order markup on own work (%) | B6: 35 | C6: Markup on materials and labour in change orders; usually your standard markup.
A7: Deposit (% of quote) | B7: 30 | C7: Shown on the quote as the deposit to request.

Sheet Quote
A1: Quote
A2: Client | B2: Example Homeowner
A3: Job | B3: Kitchen refit
A5: Material | B5: Quantity | C5: Unit cost | D5: Line cost
A6: Base units | B6: 6 | C6: 95 | D6: =IF(A6="","",ROUND(B6*C6,2)) -> 570
A7: Worktop (m) | B7: 4 | C7: 60 | D7: =IF(A7="","",ROUND(B7*C7,2)) -> 240
A8: Fixings and sundries | B8: 1 | C8: 120 | D8: =IF(A8="","",ROUND(B8*C8,2)) -> 120
D9: =IF(A9="","",ROUND(B9*C9,2))
D10: =IF(A10="","",ROUND(B10*C10,2))
D11: =IF(A11="","",ROUND(B11*C11,2))
D12: =IF(A12="","",ROUND(B12*C12,2))
D13: =IF(A13="","",ROUND(B13*C13,2))
D14: =IF(A14="","",ROUND(B14*C14,2))
D15: =IF(A15="","",ROUND(B15*C15,2))
D16: =IF(A16="","",ROUND(B16*C16,2))
D17: =IF(A17="","",ROUND(B17*C17,2))
D18: =IF(A18="","",ROUND(B18*C18,2))
D19: =IF(A19="","",ROUND(B19*C19,2))
D20: =IF(A20="","",ROUND(B20*C20,2))
A22: Labour task | B22: Hours | C22: Cost rate | D22: Labour cost
A23: Strip out | B23: 4 | C23: =IF(A23="","",Settings!$B$2) -> 45 | D23: =IF(A23="","",ROUND(B23*C23,2)) -> 180
A24: Fit units and worktop | B24: 10 | C24: =IF(A24="","",Settings!$B$2) -> 45 | D24: =IF(A24="","",ROUND(B24*C24,2)) -> 450
A25: Finishing | B25: 2 | C25: =IF(A25="","",Settings!$B$2) -> 45 | D25: =IF(A25="","",ROUND(B25*C25,2)) -> 90
C26: =IF(A26="","",Settings!$B$2) | D26: =IF(A26="","",ROUND(B26*C26,2))
C27: =IF(A27="","",Settings!$B$2) | D27: =IF(A27="","",ROUND(B27*C27,2))
C28: =IF(A28="","",Settings!$B$2) | D28: =IF(A28="","",ROUND(B28*C28,2))
C29: =IF(A29="","",Settings!$B$2) | D29: =IF(A29="","",ROUND(B29*C29,2))
C30: =IF(A30="","",Settings!$B$2) | D30: =IF(A30="","",ROUND(B30*C30,2))
C31: =IF(A31="","",Settings!$B$2) | D31: =IF(A31="","",ROUND(B31*C31,2))
C32: =IF(A32="","",Settings!$B$2) | D32: =IF(A32="","",ROUND(B32*C32,2))
A34: Subcontractor | B34: Cost
A35: Electrician | B35: 300
A43: Materials | B43: =SUM(D6:D20) -> 930
A44: Labour | B44: =SUM(D23:D32) -> 720
A45: Subcontractors (at cost) | B45: =SUM(B35:B40) -> 300
A46: Direct cost | B46: =B43+B44+B45 -> 1950
A47: Overhead | B47: =ROUND(B46*Settings!$B$3/100,2) -> 292.5
A48: Total cost | B48: =B46+B47 -> 2242.5
A49: QUOTE PRICE | B49: =ROUND(B48/(1-Settings!$B$4/100),2) -> 2803.13
A50: Profit | B50: =B49-B48 -> 560.63
...

Sheet Change Orders
A1: Change Orders
A2: Original contract price | B2: =Quote!B49 -> 2803.13
A4: # | B4: Description | C4: Materials | D4: Hours | E4: Cost rate | F4: Subcontractors | G4: Own cost | H4: Own markup | I4: Sub markup | J4: Change price | K4: Revised contract total | L4: % of original
A5: =IF(B5="","",1) -> 1 | B5: Extra double socket | C5: 40 | D5: 1.5 | E5: =IF(B5="","",Settings!$B$2) -> 45 | F5: 120 | G5: =IF(B5="","",ROUND(C5+D5*E5,2)) -> 107.5 | H5: =IF(B5="","",ROUND(G5*Settings!$B$6/100,2)) -> 37.63 | I5: =IF(B5="","",ROUND(F5*Settings!$B$5/100,2)) -> 12 | J5: =IF(B5="","",G5+H5+F5+I5) -> 277.13 | K5: =IF(B5="","",$B$2+J5) -> 3080.26 | L5: =IF(B5="","",IFERROR(ROUND(J5/$B$2*100,2),"")) -> 9.89
A6: =IF(B6="","",2) -> 2 | B6: Upgrade worktop | C6: 260 | D6: 2 | E6: =IF(B6="","",Settings!$B$2) -> 45 | F6: 0 | G6: =IF(B6="","",ROUND(C6+D6*E6,2)) -> 350 | H6: =IF(B6="","",ROUND(G6*Settings!$B$6/100,2)) -> 122.5 | I6: =IF(B6="","",ROUND(F6*Settings!$B$5/100,2)) -> 0 | J6: =IF(B6="","",G6+H6+F6+I6) -> 472.5 | K6: =IF(B6="","",K5+J6) -> 3552.76 | L6: =IF(B6="","",IFERROR(ROUND(J6/$B$2*100,2),"")) -> 16.86
A7: =IF(B7="","",3) | E7: =IF(B7="","",Settings!$B$2) | G7: =IF(B7="","",ROUND(C7+D7*E7,2)) | H7: =IF(B7="","",ROUND(G7*Settings!$B$6/100,2)) | I7: =IF(B7="","",ROUND(F7*Settings!$B$5/100,2)) | J7: =IF(B7="","",G7+H7+F7+I7) | K7: =IF(B7="","",K6+J7) | L7: =IF(B7="","",IFERROR(ROUND(J7/$B$2*100,2),""))
A8: =IF(B8="","",4) | E8: =IF(B8="","",Settings!$B$2) | G8: =IF(B8="","",ROUND(C8+D8*E8,2)) | H8: =IF(B8="","",ROUND(G8*Settings!$B$6/100,2)) | I8: =IF(B8="","",ROUND(F8*Settings!$B$5/100,2)) | J8: =IF(B8="","",G8+H8+F8+I8) | K8: =IF(B8="","",K7+J8) | L8: =IF(B8="","",IFERROR(ROUND(J8/$B$2*100,2),""))
A9: =IF(B9="","",5) | E9: =IF(B9="","",Settings!$B$2) | G9: =IF(B9="","",ROUND(C9+D9*E9,2)) | H9: =IF(B9="","",ROUND(G9*Settings!$B$6/100,2)) | I9: =IF(B9="","",ROUND(F9*Settings!$B$5/100,2)) | J9: =IF(B9="","",G9+H9+F9+I9) | K9: =IF(B9="","",K8+J9) | L9: =IF(B9="","",IFERROR(ROUND(J9/$B$2*100,2),""))
A10: =IF(B10="","",6) | E10: =IF(B10="","",Settings!$B$2) | G10: =IF(B10="","",ROUND(C10+D10*E10,2)) | H10: =IF(B10="","",ROUND(G10*Settings!$B$6/100,2)) | I10: =IF(B10="","",ROUND(F10*Settings!$B$5/100,2)) | J10: =IF(B10="","",G10+H10+F10+I10) | K10: =IF(B10="","",K9+J10) | L10: =IF(B10="","",IFERROR(ROUND(J10/$B$2*100,2),""))
A11: =IF(B11="","",7) | E11: =IF(B11="","",Settings!$B$2) | G11: =IF(B11="","",ROUND(C11+D11*E11,2)) | H11: =IF(B11="","",ROUND(G11*Settings!$B$6/100,2)) | I11: =IF(B11="","",ROUND(F11*Settings!$B$5/100,2)) | J11: =IF(B11="","",G11+H11+F11+I11) | K11: =IF(B11="","",K10+J11) | L11: =IF(B11="","",IFERROR(ROUND(J11/$B$2*100,2),""))
A12: =IF(B12="","",8) | E12: =IF(B12="","",Settings!$B$2) | G12: =IF(B12="","",ROUND(C12+D12*E12,2)) | H12: =IF(B12="","",ROUND(G12*Settings!$B$6/100,2)) | I12: =IF(B12="","",ROUND(F12*Settings!$B$5/100,2)) | J12: =IF(B12="","",G12+H12+F12+I12) | K12: =IF(B12="","",K11+J12) | L12: =IF(B12="","",IFERROR(ROUND(J12/$B$2*100,2),""))
A13: =IF(B13="","",9) | E13: =IF(B13="","",Settings!$B$2) | G13: =IF(B13="","",ROUND(C13+D13*E13,2)) | H13: =IF(B13="","",ROUND(G13*Settings!$B$6/100,2)) | I13: =IF(B13="","",ROUND(F13*Settings!$B$5/100,2)) | J13: =IF(B13="","",G13+H13+F13+I13) | K13: =IF(B13="","",K12+J13) | L13: =IF(B13="","",IFERROR(ROUND(J13/$B$2*100,2),""))
A14: =IF(B14="","",10) | E14: =IF(B14="","",Settings!$B$2) | G14: =IF(B14="","",ROUND(C14+D14*E14,2)) | H14: =IF(B14="","",ROUND(G14*Settings!$B$6/100,2)) | I14: =IF(B14="","",ROUND(F14*Settings!$B$5/100,2)) | J14: =IF(B14="","",G14+H14+F14+I14) | K14: =IF(B14="","",K13+J14) | L14: =IF(B14="","",IFERROR(ROUND(J14/$B$2*100,2),""))
A15: =IF(B15="","",11) | E15: =IF(B15="","",Settings!$B$2) | G15: =IF(B15="","",ROUND(C15+D15*E15,2)) | H15: =IF(B15="","",ROUND(G15*Settings!$B$6/100,2)) | I15: =IF(B15="","",ROUND(F15*Settings!$B$5/100,2)) | J15: =IF(B15="","",G15+H15+F15+I15) | K15: =IF(B15="","",K14+J15) | L15: =IF(B15="","",IFERROR(ROUND(J15/$B$2*100,2),""))
A16: =IF(B16="","",12) | E16: =IF(B16="","",Settings!$B$2) | G16: =IF(B16="","",ROUND(C16+D16*E16,2)) | H16: =IF(B16="","",ROUND(G16*Settings!$B$6/100,2)) | I16: =IF(B16="","",ROUND(F16*Settings!$B$5/100,2)) | J16: =IF(B16="","",G16+H16+F16+I16) | K16: =IF(B16="","",K15+J16) | L16: =IF(B16="","",IFERROR(ROUND(J16/$B$2*100,2),""))
A17: =IF(B17="","",13) | E17: =IF(B17="","",Settings!$B$2) | G17: =IF(B17="","",ROUND(C17+D17*E17,2)) | H17: =IF(B17="","",ROUND(G17*Settings!$B$6/100,2)) | I17: =IF(B17="","",ROUND(F17*Settings!$B$5/100,2)) | J17: =IF(B17="","",G17+H17+F17+I17) | K17: =IF(B17="","",K16+J17) | L17: =IF(B17="","",IFERROR(ROUND(J17/$B$2*100,2),""))
A18: =IF(B18="","",14) | E18: =IF(B18="","",Settings!$B$2) | G18: =IF(B18="","",ROUND(C18+D18*E18,2)) | H18: =IF(B18="","",ROUND(G18*Settings!$B$6/100,2)) | I18: =IF(B18="","",ROUND(F18*Settings!$B$5/100,2)) | J18: =IF(B18="","",G18+H18+F18+I18) | K18: =IF(B18="","",K17+J18) | L18: =IF(B18="","",IFERROR(ROUND(J18/$B$2*100,2),""))
A19: =IF(B19="","",15) | E19: =IF(B19="","",Settings!$B$2) | G19: =IF(B19="","",ROUND(C19+D19*E19,2)) | H19: =IF(B19="","",ROUND(G19*Settings!$B$6/100,2)) | I19: =IF(B19="","",ROUND(F19*Settings!$B$5/100,2)) | J19: =IF(B19="","",G19+H19+F19+I19) | K19: =IF(B19="","",K18+J19) | L19: =IF(B19="","",IFERROR(ROUND(J19/$B$2*100,2),""))
A20: =IF(B20="","",16) | E20: =IF(B20="","",Settings!$B$2) | G20: =IF(B20="","",ROUND(C20+D20*E20,2)) | H20: =IF(B20="","",ROUND(G20*Settings!$B$6/100,2)) | I20: =IF(B20="","",ROUND(F20*Settings!$B$5/100,2)) | J20: =IF(B20="","",G20+H20+F20+I20) | K20: =IF(B20="","",K19+J20) | L20: =IF(B20="","",IFERROR(ROUND(J20/$B$2*100,2),""))
A21: =IF(B21="","",17) | E21: =IF(B21="","",Settings!$B$2) | G21: =IF(B21="","",ROUND(C21+D21*E21,2)) | H21: =IF(B21="","",ROUND(G21*Settings!$B$6/100,2)) | I21: =IF(B21="","",ROUND(F21*Settings!$B$5/100,2)) | J21: =IF(B21="","",G21+H21+F21+I21) | K21: =IF(B21="","",K20+J21) | L21: =IF(B21="","",IFERROR(ROUND(J21/$B$2*100,2),""))
A22: =IF(B22="","",18) | E22: =IF(B22="","",Settings!$B$2) | G22: =IF(B22="","",ROUND(C22+D22*E22,2)) | H22: =IF(B22="","",ROUND(G22*Settings!$B$6/100,2)) | I22: =IF(B22="","",ROUND(F22*Settings!$B$5/100,2)) | J22: =IF(B22="","",G22+H22+F22+I22) | K22: =IF(B22="","",K21+J22) | L22: =IF(B22="","",IFERROR(ROUND(J22/$B$2*100,2),""))
A23: =IF(B23="","",19) | E23: =IF(B23="","",Settings!$B$2) | G23: =IF(B23="","",ROUND(C23+D23*E23,2)) | H23: =IF(B23="","",ROUND(G23*Settings!$B$6/100,2)) | I23: =IF(B23="","",ROUND(F23*Settings!$B$5/100,2)) | J23: =IF(B23="","",G23+H23+F23+I23) | K23: =IF(B23="","",K22+J23) | L23: =IF(B23="","",IFERROR(ROUND(J23/$B$2*100,2),""))
A24: =IF(B24="","",20) | E24: =IF(B24="","",Settings!$B$2) | G24: =IF(B24="","",ROUND(C24+D24*E24,2)) | H24: =IF(B24="","",ROUND(G24*Settings!$B$6/100,2)) | I24: =IF(B24="","",ROUND(F24*Settings!$B$5/100,2)) | J24: =IF(B24="","",G24+H24+F24+I24) | K24: =IF(B24="","",K23+J24) | L24: =IF(B24="","",IFERROR(ROUND(J24/$B$2*100,2),""))
A25: Totals | J25: =SUM(J5:J24) -> 749.63
A26: Revised contract total | J26: =$B$2+J25 -> 3552.76
A27: All changes as % of original | J27: =IFERROR(ROUND(J25/$B$2*100,2),"") -> 26.74

Sheet Jobs
A1: Jobs
A2: One row per job. Enter actual materials, hours and subcontractor cost as the job runs; profit and margin update.
A4: Job | B4: Client | C4: Status | D4: Quoted price | E4: Change orders | F4: Contract total | G4: Actual materials | H4: Actual hours | I4: Cost rate | J4: Actual subs | K4: Direct cost | L4: Overhead | M4: Total cost | N4: Profit | O4: Margin % | P4: Invoiced | Q4: Paid | R4: Outstanding
A5: Kitchen refit | B5: Example Homeowner | C5: active | D5: 3000 | E5: 450 | F5: =IF(A5="","",D5+E5) -> 3450 | G5: 980 | H5: 18 | I5: =IF(A5="","",Settings!$B$2) -> 45 | J5: 300 | K5: =IF(A5="","",ROUND(G5+H5*I5+J5,2)) -> 2090 | L5: =IF(A5="","",ROUND(K5*Settings!$B$3/100,2)) -> 313.5 | M5: =IF(A5="","",K5+L5) -> 2403.5 | N5: =IF(A5="","",F5-M5) -> 1046.5 | O5: =IF(A5="","",IFERROR(ROUND(N5/F5*100,2),"")) -> 30.33 | P5: 3450 | Q5: 1035 | R5: =IF(A5="","",P5-Q5) -> 2415
A6: Bathroom tiling | B6: Sample Ltd | C6: done | D6: 1800 | E6: 0 | F6: =IF(A6="","",D6+E6) -> 1800 | G6: 520 | H6: 14 | I6: =IF(A6="","",Settings!$B$2) -> 45 | J6: 0 | K6: =IF(A6="","",ROUND(G6+H6*I6+J6,2)) -> 1150 | L6: =IF(A6="","",ROUND(K6*Settings!$B$3/100,2)) -> 172.5 | M6: =IF(A6="","",K6+L6) -> 1322.5 | N6: =IF(A6="","",F6-M6) -> 477.5 | O6: =IF(A6="","",IFERROR(ROUND(N6/F6*100,2),"")) -> 26.53 | P6: 1800 | Q6: 1800 | R6: =IF(A6="","",P6-Q6) -> 0
A7: Garden wall | B7: Demo Client | C7: done | D7: 2400 | E7: 200 | F7: =IF(A7="","",D7+E7) -> 2600 | G7: 900 | H7: 20 | I7: =IF(A7="","",Settings!$B$2) -> 45 | J7: 250 | K7: =IF(A7="","",ROUND(G7+H7*I7+J7,2)) -> 2050 | L7: =IF(A7="","",ROUND(K7*Settings!$B$3/100,2)) -> 307.5 | M7: =IF(A7="","",K7+L7) -> 2357.5 | N7: =IF(A7="","",F7-M7) -> 242.5 | O7: =IF(A7="","",IFERROR(ROUND(N7/F7*100,2),"")) -> 9.33 | P7: 2600 | Q7: 2600 | R7: =IF(A7="","",P7-Q7) -> 0
F8: =IF(A8="","",D8+E8) | I8: =IF(A8="","",Settings!$B$2) | K8: =IF(A8="","",ROUND(G8+H8*I8+J8,2)) | L8: =IF(A8="","",ROUND(K8*Settings!$B$3/100,2)) | M8: =IF(A8="","",K8+L8) | N8: =IF(A8="","",F8-M8) | O8: =IF(A8="","",IFERROR(ROUND(N8/F8*100,2),"")) | R8: =IF(A8="","",P8-Q8)
F9: =IF(A9="","",D9+E9) | I9: =IF(A9="","",Settings!$B$2) | K9: =IF(A9="","",ROUND(G9+H9*I9+J9,2)) | L9: =IF(A9="","",ROUND(K9*Settings!$B$3/100,2)) | M9: =IF(A9="","",K9+L9) | N9: =IF(A9="","",F9-M9) | O9: =IF(A9="","",IFERROR(ROUND(N9/F9*100,2),"")) | R9: =IF(A9="","",P9-Q9)
F10: =IF(A10="","",D10+E10) | I10: =IF(A10="","",Settings!$B$2) | K10: =IF(A10="","",ROUND(G10+H10*I10+J10,2)) | L10: =IF(A10="","",ROUND(K10*Settings!$B$3/100,2)) | M10: =IF(A10="","",K10+L10) | N10: =IF(A10="","",F10-M10) | O10: =IF(A10="","",IFERROR(ROUND(N10/F10*100,2),"")) | R10: =IF(A10="","",P10-Q10)
F11: =IF(A11="","",D11+E11) | I11: =IF(A11="","",Settings!$B$2) | K11: =IF(A11="","",ROUND(G11+H11*I11+J11,2)) | L11: =IF(A11="","",ROUND(K11*Settings!$B$3/100,2)) | M11: =IF(A11="","",K11+L11) | N11: =IF(A11="","",F11-M11) | O11: =IF(A11="","",IFERROR(ROUND(N11/F11*100,2),"")) | R11: =IF(A11="","",P11-Q11)
F12: =IF(A12="","",D12+E12) | I12: =IF(A12="","",Settings!$B$2) | K12: =IF(A12="","",ROUND(G12+H12*I12+J12,2)) | L12: =IF(A12="","",ROUND(K12*Settings!$B$3/100,2)) | M12: =IF(A12="","",K12+L12) | N12: =IF(A12="","",F12-M12) | O12: =IF(A12="","",IFERROR(ROUND(N12/F12*100,2),"")) | R12: =IF(A12="","",P12-Q12)
F13: =IF(A13="","",D13+E13) | I13: =IF(A13="","",Settings!$B$2) | K13: =IF(A13="","",ROUND(G13+H13*I13+J13,2)) | L13: =IF(A13="","",ROUND(K13*Settings!$B$3/100,2)) | M13: =IF(A13="","",K13+L13) | N13: =IF(A13="","",F13-M13) | O13: =IF(A13="","",IFERROR(ROUND(N13/F13*100,2),"")) | R13: =IF(A13="","",P13-Q13)
F14: =IF(A14="","",D14+E14) | I14: =IF(A14="","",Settings!$B$2) | K14: =IF(A14="","",ROUND(G14+H14*I14+J14,2)) | L14: =IF(A14="","",ROUND(K14*Settings!$B$3/100,2)) | M14: =IF(A14="","",K14+L14) | N14: =IF(A14="","",F14-M14) | O14: =IF(A14="","",IFERROR(ROUND(N14/F14*100,2),"")) | R14: =IF(A14="","",P14-Q14)
F15: =IF(A15="","",D15+E15) | I15: =IF(A15="","",Settings!$B$2) | K15: =IF(A15="","",ROUND(G15+H15*I15+J15,2)) | L15: =IF(A15="","",ROUND(K15*Settings!$B$3/100,2)) | M15: =IF(A15="","",K15+L15) | N15: =IF(A15="","",F15-M15) | O15: =IF(A15="","",IFERROR(ROUND(N15/F15*100,2),"")) | R15: =IF(A15="","",P15-Q15)
F16: =IF(A16="","",D16+E16) | I16: =IF(A16="","",Settings!$B$2) | K16: =IF(A16="","",ROUND(G16+H16*I16+J16,2)) | L16: =IF(A16="","",ROUND(K16*Settings!$B$3/100,2)) | M16: =IF(A16="","",K16+L16) | N16: =IF(A16="","",F16-M16) | O16: =IF(A16="","",IFERROR(ROUND(N16/F16*100,2),"")) | R16: =IF(A16="","",P16-Q16)
F17: =IF(A17="","",D17+E17) | I17: =IF(A17="","",Settings!$B$2) | K17: =IF(A17="","",ROUND(G17+H17*I17+J17,2)) | L17: =IF(A17="","",ROUND(K17*Settings!$B$3/100,2)) | M17: =IF(A17="","",K17+L17) | N17: =IF(A17="","",F17-M17) | O17: =IF(A17="","",IFERROR(ROUND(N17/F17*100,2),"")) | R17: =IF(A17="","",P17-Q17)
F18: =IF(A18="","",D18+E18) | I18: =IF(A18="","",Settings!$B$2) | K18: =IF(A18="","",ROUND(G18+H18*I18+J18,2)) | L18: =IF(A18="","",ROUND(K18*Settings!$B$3/100,2)) | M18: =IF(A18="","",K18+L18) | N18: =IF(A18="","",F18-M18) | O18: =IF(A18="","",IFERROR(ROUND(N18/F18*100,2),"")) | R18: =IF(A18="","",P18-Q18)
F19: =IF(A19="","",D19+E19) | I19: =IF(A19="","",Settings!$B$2) | K19: =IF(A19="","",ROUND(G19+H19*I19+J19,2)) | L19: =IF(A19="","",ROUND(K19*Settings!$B$3/100,2)) | M19: =IF(A19="","",K19+L19) | N19: =IF(A19="","",F19-M19) | O19: =IF(A19="","",IFERROR(ROUND(N19/F19*100,2),"")) | R19: =IF(A19="","",P19-Q19)
... F40: =IF(A40="","",D40+E40) | I40: =IF(A40="","",Settings!$B$2) | K40: =IF(A40="","",ROUND(G40+H40*I40+J40,2)) | L40: =IF(A40="","",ROUND(K40*Settings!$B$3/100,2)) | M40: =IF(A40="","",K40+L40) | N40: =IF(A40="","",F40-M40) | O40: =IF(A40="","",IFERROR(ROUND(N40/F40*100,2),"")) | R40: =IF(A40="","",P40-Q40)
A41: Totals | D41: =SUM(D5:D40) -> 7200 | E41: =SUM(E5:E40) -> 650 | F41: =SUM(F5:F40) -> 7850 | G41: =SUM(G5:G40) -> 2400 | H41: =SUM(H5:H40) -> 52 | J41: =SUM(J5:J40) -> 550 | K41: =SUM(K5:K40) -> 5290 | L41: =SUM(L5:L40) -> 793.5 | M41: =SUM(M5:M40) -> 6083.5 | N41: =SUM(N5:N40) -> 1766.5 | O41: =IFERROR(ROUND(N41/F41*100,2),"") -> 22.5 | P41: =SUM(P5:P40) -> 7850 | Q41: =SUM(Q5:Q40) -> 5435 | R41: =SUM(R5:R40) -> 2415

Sheet Summary
A1: Summary
A2: Jobs tracked | B2: =COUNTA(Jobs!A5:A40) -> 3
A3: Contract value (quotes + change orders) | B3: =Jobs!F41 -> 7850
A4: Total cost including overhead | B4: =Jobs!M41 -> 6083.5
A5: Profit | B5: =Jobs!N41 -> 1766.5
A6: Overall margin % | B6: =IFERROR(ROUND(B5/B3*100,2),"") -> 22.5 | C6: profit ÷ contract value
A7: Target margin % (Settings) | B7: =Settings!$B$4 -> 20
A8: Jobs below the target margin | B8: =COUNTIF(Jobs!O5:O40,"<"&Settings!$B$4) -> 1
A9: Change orders as % of quoted prices | B9: =IFERROR(ROUND(Jobs!E41/Jobs!D41*100,2),"") -> 9.03
A10: Hours worked | B10: =Jobs!H41 -> 52
A11: Average profit per hour | B11: =IFERROR(ROUND(B5/B10,2),"") -> 33.97 | C11: profit ÷ hours
A12: Invoiced | B12: =Jobs!P41 -> 7850
A13: Paid | B13: =Jobs!Q41 -> 5435
A14: Outstanding | B14: =Jobs!R41 -> 2415
