Workbook

Sheet Start Here
A1: Event & Catering Quote Workbook
A2: by Knackdesk · knackdesk.com
A4: HOW TO USE
A5: 1. Settings: your labour rates, staffing ratios, setup and minimum hours, drinks-per-guest estimates, target margin and deposit. Every other sheet reads them.
A6: 2. Quote: client, event, guests and hours, then the menu (cost per guest), rentals and other costs. Staffing, bar, total cost, price at your target margin, price per guest, deposit and balance are calculated.
A7: 3. Bar: the drinks estimate for the quote, split by beer, wine and spirits with your cost per serving. Shares must total 100.
A8: 4. Events: one row per event you quoted or ran, with the quoted price and the actual costs. Profit, margin and outstanding balance are calculated, with totals in row 41.
A9: 5. Summary: events tracked, quoted total, cost, profit, margin, average price per guest, events below target margin and money outstanding, read from the Events sheet.
A11: LEGEND
A12: Blue text = a cell you type into. Black text = a formula, leave it alone. Yellow fill = key inputs.
A14: DEFINITIONS
A15: Price at target margin = total cost ÷ (1 − target margin %). A 30% margin means 30% of the price you charge is profit, which is not the same as a 30% markup on cost.
... A21: Arithmetic only; not financial advice.

Sheet Settings
A1: Settings
A2: Server labour rate per hour | B2: 22 | C2: What a server costs you per hour, including any employer costs.
A3: Bartender rate per hour | B3: 25 | C3: What a bartender costs you per hour.
A4: Guests per server | B4: 25 | C4: Common starting point; plated service often needs fewer guests per server.
A5: Guests per bartender | B5: 50 | C5: Common starting point; a full bar or cocktails may need more bartenders.
A6: Setup and teardown hours | B6: 2 | C6: Added to the event hours for every staff member.
A7: Minimum hours per staff | B7: 4 | C7: Minimum paid shift length.
A8: Drinks per guest, first hour | B8: 2 | C8: Estimate; adjust for your crowd.
A9: Drinks per guest, each later hour | B9: 1 | C9: Estimate; adjust for your crowd.
A10: Target margin (% of price) | B10: 30 | C10: Profit as a share of the price you charge, not a markup on cost.
A11: Deposit (% of price) | B11: 40 | C11: Share of the price collected up front.

Sheet Quote
A1: Quote
A2: Client | B2: Sample client
A3: Event name | B3: Company dinner
A4: Event date | B4: 46558
A5: Guests | B5: 100
A6: Event hours | B6: 5
A7: Menu: cost per guest for each course or item. Rentals: fixed costs for this event.
A8: Menu item | B8: Cost per guest | C8: Per-guest total | D8: Event total
A9: Starter | B9: 6 | C9: =IF(A9="","",B9) -> 6 | D9: =IF(A9="","",ROUND(B9*$B$5,2)) -> 600
A10: Main | B10: 14 | C10: =IF(A10="","",B10) -> 14 | D10: =IF(A10="","",ROUND(B10*$B$5,2)) -> 1400
A11: Dessert | B11: 5 | C11: =IF(A11="","",B11) -> 5 | D11: =IF(A11="","",ROUND(B11*$B$5,2)) -> 500
C12: =IF(A12="","",B12) | D12: =IF(A12="","",ROUND(B12*$B$5,2))
C13: =IF(A13="","",B13) | D13: =IF(A13="","",ROUND(B13*$B$5,2))
C14: =IF(A14="","",B14) | D14: =IF(A14="","",ROUND(B14*$B$5,2))
C15: =IF(A15="","",B15) | D15: =IF(A15="","",ROUND(B15*$B$5,2))
C16: =IF(A16="","",B16) | D16: =IF(A16="","",ROUND(B16*$B$5,2))
C17: =IF(A17="","",B17) | D17: =IF(A17="","",ROUND(B17*$B$5,2))
C18: =IF(A18="","",B18) | D18: =IF(A18="","",ROUND(B18*$B$5,2))
C19: =IF(A19="","",B19) | D19: =IF(A19="","",ROUND(B19*$B$5,2))
C20: =IF(A20="","",B20) | D20: =IF(A20="","",ROUND(B20*$B$5,2))
A21: Food total | C21: =SUM(C9:C20) -> 25 | D21: =SUM(D9:D20) -> 2500
A23: Rentals and other costs | B23: Cost
A24: Tables and linen | B24: 450
A25: Sound | B25: 300
A34: Rentals total | B34: =SUM(B24:B33) -> 750
A36: Staffing
A37: Hours per staff member | B37: =MAX($B$6+Settings!$B$6,Settings!$B$7) -> 7 | C37: event hours + setup and teardown, at least the minimum shift
A38: Servers needed | B38: =IFERROR(ROUNDUP($B$5/Settings!$B$4,0),0) -> 4 | C38: guests ÷ guests per server, rounded up
A39: Server cost | B39: =ROUND(B38*B37*Settings!$B$2,2) -> 616 | C39: servers × hours × server rate
A40: Bartenders needed | B40: =IFERROR(ROUNDUP($B$5/Settings!$B$5,0),0) -> 2 | C40: guests ÷ guests per bartender, rounded up
A41: Bartender cost | B41: =ROUND(B40*B37*Settings!$B$3,2) -> 350 | C41: bartenders × hours × bartender rate
A42: Staffing total | B42: =B39+B41 -> 966
A44: Quote summary
A45: Food total | B45: =D21 -> 2500
A46: Staffing total | B46: =B42 -> 966
A47: Bar total | B47: =Bar!E9 -> 1800 | C47: from the Bar sheet
A48: Rentals and other | B48: =B34 -> 750
A49: Total cost | B49: =B45+B46+B47+B48 -> 6016
A50: Price at target margin | B50: =IFERROR(ROUND(B49/(1-Settings!$B$10/100),2),0) -> 8594.29 | C50: total cost ÷ (1 − target margin %)
A51: Profit | B51: =B50-B49 -> 2578.29
...

Sheet Bar
A1: Bar
A2: Guests (from Quote) | B2: =Quote!$B$5 -> 100
A3: Event hours (from Quote) | B3: =Quote!$B$6 -> 5
A4: Drinks total | B4: =ROUND(Quote!$B$5*(Settings!$B$8+Settings!$B$9*MAX(Quote!$B$6-1,0)),0) -> 600 | C4: guests × (first-hour drinks + later-hour drinks × (hours − 1))
A5: Drink type | B5: Share % | C5: Drinks | D5: Cost per serving | E5: Cost
A6: Beer | B6: 40 | C6: =IF(A6="","",ROUND($B$4*B6/100,0)) -> 240 | D6: 2.5 | E6: =IF(A6="","",ROUND(C6*D6,2)) -> 600
A7: Wine | B7: 40 | C7: =IF(A7="","",ROUND($B$4*B7/100,0)) -> 240 | D7: 3 | E7: =IF(A7="","",ROUND(C7*D7,2)) -> 720
A8: Spirits | B8: 20 | C8: =IF(A8="","",ROUND($B$4*B8/100,0)) -> 120 | D8: 4 | E8: =IF(A8="","",ROUND(C8*D8,2)) -> 480
A9: Total | B9: =SUM(B6:B8) -> 100 | C9: =SUM(C6:C8) -> 600 | E9: =SUM(E6:E8) -> 1800 | F9: =IF(ROUND(B9,2)=100,"","Shares must total 100")
A10: Bar cost per guest | B10: =IFERROR(ROUND(E9/B2,2),0) -> 18

Sheet Events
A1: Events
A2: One row per event. Enter the quoted price and the actual costs once known; profit, margin and outstanding are calculated.
A4: Event | B4: Date | C4: Client | D4: Guests | E4: Status | F4: Quoted price | G4: Actual food | H4: Actual staffing | I4: Actual bar | J4: Actual rentals | K4: Total cost | L4: Profit | M4: Margin % | N4: Invoiced | O4: Paid | P4: Outstanding
A5: Harbour wedding | B5: 46158 | C5: Smith family | D5: 120 | E5: done | F5: 10600 | G5: 3600 | H5: 1450 | I5: 1300 | J5: 900 | K5: =IF(A5="","",G5+H5+I5+J5) -> 7250 | L5: =IF(A5="","",F5-K5) -> 3350 | M5: =IF(A5="","",IFERROR(ROUND(L5/F5*100,2),"")) -> 31.6 | N5: 10600 | O5: 10600 | P5: =IF(A5="","",N5-O5) -> 0
A6: Summer staff party | B6: 46214 | C6: Acme Ltd | D6: 80 | E6: done | F6: 6300 | G6: 2100 | H6: 980 | I6: 820 | J6: 450 | K6: =IF(A6="","",G6+H6+I6+J6) -> 4350 | L6: =IF(A6="","",F6-K6) -> 1950 | M6: =IF(A6="","",IFERROR(ROUND(L6/F6*100,2),"")) -> 30.95 | N6: 6300 | O6: 3000 | P6: =IF(A6="","",N6-O6) -> 3300
A7: 50th birthday | B7: 46291 | C7: J. Lee | D7: 45 | E7: confirmed | F7: 2900 | G7: 950 | H7: 600 | I7: 520 | J7: 300 | K7: =IF(A7="","",G7+H7+I7+J7) -> 2370 | L7: =IF(A7="","",F7-K7) -> 530 | M7: =IF(A7="","",IFERROR(ROUND(L7/F7*100,2),"")) -> 18.28 | N7: 1160 | O7: 1160 | P7: =IF(A7="","",N7-O7) -> 0
K8: =IF(A8="","",G8+H8+I8+J8) | L8: =IF(A8="","",F8-K8) | M8: =IF(A8="","",IFERROR(ROUND(L8/F8*100,2),"")) | P8: =IF(A8="","",N8-O8)
K9: =IF(A9="","",G9+H9+I9+J9) | L9: =IF(A9="","",F9-K9) | M9: =IF(A9="","",IFERROR(ROUND(L9/F9*100,2),"")) | P9: =IF(A9="","",N9-O9)
K10: =IF(A10="","",G10+H10+I10+J10) | L10: =IF(A10="","",F10-K10) | M10: =IF(A10="","",IFERROR(ROUND(L10/F10*100,2),"")) | P10: =IF(A10="","",N10-O10)
K11: =IF(A11="","",G11+H11+I11+J11) | L11: =IF(A11="","",F11-K11) | M11: =IF(A11="","",IFERROR(ROUND(L11/F11*100,2),"")) | P11: =IF(A11="","",N11-O11)
K12: =IF(A12="","",G12+H12+I12+J12) | L12: =IF(A12="","",F12-K12) | M12: =IF(A12="","",IFERROR(ROUND(L12/F12*100,2),"")) | P12: =IF(A12="","",N12-O12)
K13: =IF(A13="","",G13+H13+I13+J13) | L13: =IF(A13="","",F13-K13) | M13: =IF(A13="","",IFERROR(ROUND(L13/F13*100,2),"")) | P13: =IF(A13="","",N13-O13)
K14: =IF(A14="","",G14+H14+I14+J14) | L14: =IF(A14="","",F14-K14) | M14: =IF(A14="","",IFERROR(ROUND(L14/F14*100,2),"")) | P14: =IF(A14="","",N14-O14)
K15: =IF(A15="","",G15+H15+I15+J15) | L15: =IF(A15="","",F15-K15) | M15: =IF(A15="","",IFERROR(ROUND(L15/F15*100,2),"")) | P15: =IF(A15="","",N15-O15)
K16: =IF(A16="","",G16+H16+I16+J16) | L16: =IF(A16="","",F16-K16) | M16: =IF(A16="","",IFERROR(ROUND(L16/F16*100,2),"")) | P16: =IF(A16="","",N16-O16)
K17: =IF(A17="","",G17+H17+I17+J17) | L17: =IF(A17="","",F17-K17) | M17: =IF(A17="","",IFERROR(ROUND(L17/F17*100,2),"")) | P17: =IF(A17="","",N17-O17)
K18: =IF(A18="","",G18+H18+I18+J18) | L18: =IF(A18="","",F18-K18) | M18: =IF(A18="","",IFERROR(ROUND(L18/F18*100,2),"")) | P18: =IF(A18="","",N18-O18)
K19: =IF(A19="","",G19+H19+I19+J19) | L19: =IF(A19="","",F19-K19) | M19: =IF(A19="","",IFERROR(ROUND(L19/F19*100,2),"")) | P19: =IF(A19="","",N19-O19)
... K40: =IF(A40="","",G40+H40+I40+J40) | L40: =IF(A40="","",F40-K40) | M40: =IF(A40="","",IFERROR(ROUND(L40/F40*100,2),"")) | P40: =IF(A40="","",N40-O40)
A41: Total | D41: =SUM(D5:D40) -> 245 | F41: =SUM(F5:F40) -> 19800 | G41: =SUM(G5:G40) -> 6650 | H41: =SUM(H5:H40) -> 3030 | I41: =SUM(I5:I40) -> 2640 | J41: =SUM(J5:J40) -> 1650 | K41: =SUM(K5:K40) -> 13970 | L41: =SUM(L5:L40) -> 5830 | M41: =IFERROR(ROUND(L41/F41*100,2),0) -> 29.44 | N41: =SUM(N5:N40) -> 18060 | O41: =SUM(O5:O40) -> 14760 | P41: =SUM(P5:P40) -> 3300

Sheet Summary
A1: Summary
A2: Events tracked | B2: =COUNTA(Events!A5:A40) -> 3
A3: Quoted total | B3: =Events!F41 -> 19800
A4: Total cost | B4: =Events!K41 -> 13970
A5: Profit | B5: =Events!L41 -> 5830
A6: Margin % | B6: =Events!M41 -> 29.44 | C6: profit ÷ quoted total
A7: Total guests | B7: =Events!D41 -> 245
A8: Average price per guest | B8: =IFERROR(ROUND(B3/B7,2),0) -> 80.82 | C8: quoted total ÷ total guests
A9: Events below target margin | B9: =COUNTIF(Events!M5:M40,"<"&Settings!$B$10) -> 1 | C9: margin % under Settings target
A10: Outstanding | B10: =Events!P41 -> 3300 | C10: invoiced − paid
